#VRML_SIM V8.5 utf8
WorldInfo {
  info [
    "Single motor example test"
    "Q2 2020"
  ]
}
Viewpoint {
  orientation 1 0 0 -0.8
  position 0.25 0.708035 0.894691
}
Background {
  skyColor [
    0.4 0.4 0.4
  ]
}
PointLight {
  ambientIntensity 0.54
  intensity 0.5
  location 0 1 0
}
DEF EXAMPLE Robot {
  name "example"
  controller "<extern>"
  translation 0 0 0
  children [
    HingeJoint {
      jointParameters HingeJointParameters {
        anchor 0 0 0
      }
      device [
        RotationalMotor {
          name "motor1"
        }
        PositionSensor {}
      ]
      endPoint Solid {
        translation 0 0 0
        children [
          Shape {
            appearance PBRAppearance {
              baseColor 1 0.8 1
              roughness 1
              metalness 0
            }
            geometry Box {
              size 0.1 0.1 0.1
            }
          }
        ]
      }
    }
  ]
}
