#VRML_SIM R2020b utf8
# license: Apache License 2.0
# license url: http://www.apache.org/licenses/LICENSE-2.0
# This is a proto file for Webots for the ar2
# Extracted from: ar2.urdf

PROTO ar2 [
  field  SFVec3f     translation     0 0 0
  field  SFRotation  rotation        1 0 0 -1.5708
  field  SFString    name            "ar2"  # Is `Robot.name`.
  field  SFString    controller      "void" # Is `Robot.controller`.
  field  MFString    controllerArgs  []     # Is `Robot.controllerArgs`.
  field  SFString    customData      ""     # Is `Robot.customData`.
  field  SFBool      supervisor      FALSE  # Is `Robot.supervisor`.
  field  SFBool      synchronization TRUE   # Is `Robot.synchronization`.
  field  SFBool      selfCollision   FALSE  # Is `Robot.selfCollision`.
  field  SFBool      staticBase      TRUE   # Defines if the robot base should be pinned to the static environment.
  field  MFNode      toolSlot        []     # Extend the robot with new nodes at the end of the arm.
]
{
  Robot {
    translation IS translation
    rotation IS rotation
    controller IS controller
    controllerArgs IS controllerArgs
    customData IS customData
    supervisor IS supervisor
    synchronization IS synchronization
    selfCollision IS selfCollision
    children [
      ar2_base_linkMesh {
      }
      HingeJoint {
        jointParameters HingeJointParameters {
          axis 0.000000 0.000007 -1.000000
          anchor 0.000000 0.000000 0.003445
          dampingConstant 0.0
          staticFriction 0.0
        }
        device [
          RotationalMotor {
            name "joint_1"
            maxTorque 10000
          }
          PositionSensor {
            name "joint_1_sensor"
          }
        ]
        endPoint Solid {
          translation 0.000000 0.000000 0.003445
          rotation 1.000000 -0.000008 0.000000 3.141600
          children [
            ar2_link_1Mesh {
            }
            HingeJoint {
              jointParameters HingeJointParameters {
                axis -1.000000 0.000006 -0.000003
                anchor 0.000000 0.064146 -0.166080
                dampingConstant 0.0
                staticFriction 0.0
              }
              device [
                RotationalMotor {
                  name "joint_2"
                  maxTorque 10000
                }
                PositionSensor {
                  name "joint_2_sensor"
                }
              ]
              endPoint Solid {
                translation 0.000000 0.064146 -0.166080
                rotation 0.654653 -0.377966 -0.654653 2.418864
                children [
                  ar2_link_2Mesh {
                  }
                  HingeJoint {
                    jointParameters HingeJointParameters {
                      axis 0.000000 -0.000000 -1.000000
                      anchor 0.152500 -0.264140 0.000000
                      dampingConstant 0.0
                      staticFriction 0.0
                    }
                    device [
                      RotationalMotor {
                        name "joint_3"
                        maxTorque 10000
                      }
                      PositionSensor {
                        name "joint_3_sensor"
                      }
                    ]
                    endPoint Solid {
                      translation 0.152500 -0.264140 0.000000
                      rotation -0.000000 -0.000000 -1.000000 2.618000
                      children [
                        ar2_link_3Mesh {
                        }
                        HingeJoint {
                          jointParameters HingeJointParameters {
                            axis 1.000000 -0.000000 0.000001
                            anchor 0.000000 0.000000 0.006750
                            dampingConstant 0.0
                            staticFriction 0.0
                          }
                          device [
                            RotationalMotor {
                              name "joint_4"
                              maxTorque 10000
                            }
                            PositionSensor {
                              name "joint_4_sensor"
                            }
                          ]
                          endPoint Solid {
                            translation 0.000000 0.000000 0.006750
                            rotation 0.155144 -0.975634 -0.155144 1.595463
                            children [
                              ar2_link_4Mesh {
                              }
                              HingeJoint {
                                jointParameters HingeJointParameters {
                                  axis 0.950675 0.310190 0.000000
                                  anchor 0.000000 0.000000 -0.222250
                                  dampingConstant 0.0
                                  staticFriction 0.0
                                }
                                device [
                                  RotationalMotor {
                                    name "joint_5"
                                    maxTorque 10000
                                  }
                                  PositionSensor {
                                    name "joint_5_sensor"
                                  }
                                ]
                                endPoint Solid {
                                  translation 0.000000 0.000000 -0.222250
                                  rotation 0.157044 -0.987592 0.000004 3.141594
                                  children [
                                    ar2_link_5Mesh {
                                    }
                                    HingeJoint {
                                      jointParameters HingeJointParameters {
                                        axis 0.000000 -0.000000 -1.000000
                                        anchor -0.000294 0.000000 0.021170
                                        dampingConstant 0.0
                                        staticFriction 0.0
                                      }
                                      device [
                                        RotationalMotor {
                                          name "joint_6"
                                          maxTorque 10000
                                        }
                                        PositionSensor {
                                          name "joint_6_sensor"
                                        }
                                      ]
                                      endPoint Solid {
                                        translation -0.000294 0.000000 0.021170
                                        rotation -0.000000 0.000000 1.000000 3.141600
                                        children [
                                          ar2_link_6Mesh {
                                          }
                                          Group {
                                            children IS toolSlot
                                          }
                                        ]
                                        name "link_6"
                                        boundingObject USE link_6
                                        physics Physics {
                                          density -1
                                          mass 0.013863
                                          centerOfMass [ 0.000000 -0.000000 0.009143 ]
                                          inertiaMatrix [
                                            1.359600e-06 1.715700e-06 2.433200e-06
                                            3.058500e-13 5.710200e-14 6.336900e-09
                                          ]
                                        }
                                      }
                                    }
                                  ]
                                  name "link_5"
                                  boundingObject USE link_5
                                  physics Physics {
                                    density -1
                                    mass 0.115620
                                    centerOfMass [ 0.001507 -0.000013 -0.012585 ]
                                    inertiaMatrix [
                                      5.503500e-05 8.292100e-05 5.251800e-05
                                      -1.019000e-08 -2.624300e-06 1.443700e-08
                                    ]
                                  }
                                }
                              }
                            ]
                            name "link_4"
                            boundingObject USE link_4
                            physics Physics {
                              density -1
                              mass 0.349360
                              centerOfMass [ -0.001680 -0.000573 -0.074404 ]
                              inertiaMatrix [
                                3.053200e-03 3.103300e-03 2.226400e-04
                                -1.861500e-05 -7.004700e-05 -2.330100e-05
                              ]
                            }
                          }
                        }
                      ]
                      name "link_3"
                      boundingObject USE link_3
                      physics Physics {
                        density -1
                        mass 0.178700
                        centerOfMass [ -0.000298 -0.023661 -0.001912 ]
                        inertiaMatrix [
                          1.685000e-04 1.286500e-04 2.074400e-04
                          -2.771300e-05 5.688500e-06 2.925600e-05
                        ]
                      }
                    }
                  }
                ]
                name "link_2"
                boundingObject USE link_2
                physics Physics {
                  density -1
                  mass 0.577380
                  centerOfMass [ 0.064818 -0.111890 -0.038671 ]
                  inertiaMatrix [
                    4.731200e-03 2.083600e-03 5.612900e-03
                    2.262400e-03 3.214400e-04 -5.656900e-04
                  ]
                }
              }
            }
          ]
          name "link_1"
          boundingObject USE link_1
          physics Physics {
            density -1
            mass 0.880650
            centerOfMass [ -0.022706 0.042940 -0.122050 ]
            inertiaMatrix [
              3.400000e-03 4.177800e-03 2.707700e-03
              4.229600e-04 -8.923100e-04 1.084800e-03
            ]
          }
        }
      }
    ]
    name IS name 
    boundingObject USE base_link
    %{ if fields.staticBase.value == false then }%
    physics Physics {
      density -1
      mass 0.710200
      centerOfMass [ -0.000005 0.054174 0.038824 ]
      inertiaMatrix [
        3.994300e-03 1.494600e-03 4.255400e-03
        3.697000e-07 -5.736400e-08 -3.605100e-04
      ]
    }
    %{ end }%
  }
}
